Workbook

Sheet Piano Finanziario
A1: ORTI | C1: 2025 | O1: 2026
C2: GENNAIO | D2: FEBBRAIO | E2: MARZO | F2: APRILE | G2: MAGGIO | H2: GIUGNO | I2: LUGLIO | J2: AGOSTO | K2: SETTEMBRE | L2: OTTOBRE | M2: NOVEMBRE | N2: DICEMBRE | O2: GENNAIO | P2: FEBBRAIO | Q2: MARZO | R2: APRILE
A3: SALDO MESE PRECED | K3: =K36 -> 1210700.7 | L3: =K48 -> 1405286.3 | M3: =L48 -> 1330621.4 | N3: =M48 -> 1008715.6 | O3: =N48 -> 786654.08 | P3: =O48 -> 653447.21 | Q3: =P48 -> 631943 | R3: =Q48 -> 618743.07
T4: TOTALI/TEST
A5: Entrate Hotel | K5: 580993.58 | L5: 314259.64 | T5: =SUM(C5:S5) -> 895253.22
A6: Entrate Residence | K6: =135403.58*0.3333 -> 45130.013 | L6: =52954.18*0.3333 -> 17649.628 | T6: =SUM(C6:S6) -> 62779.641
A7: Entrate CVM | K7: 24116.47 | L7: 15062.02 | T7: =SUM(C7:S7) -> 39178.49
A8: Entrate Supermercato | D8: 0 | E8: 0 | K8: 25620 | L8: 25620 | M8: 25620 | N8: 25620 | O8: 25620 | P8: 25620 | Q8: 25620 | R8: 25620 | T8: =SUM(C8:S8) -> 204960
A9: Rientro Sospesi | F9: 0 | K9: 25000 | L9: 25000 | M9: 10000 | T9: =SUM(C9:S9) -> 60000
A10: Caparre Intur | F10: 0 | T10: =SUM(C10:S10) -> 0
A11: TOTALE ENTRATE | C11: =SUM(C5:C8) -> 0 | D11: =SUM(D5:D10) -> 0 | E11: =SUM(E5:E10) -> 0 | F11: =SUM(F5:F10) -> 0 | G11: =SUM(G5:G10) -> 0 | H11: =SUM(H5:H10) -> 0 | I11: =SUM(I5:I10) -> 0 | J11: =SUM(J5:J10) -> 0 | K11: =SUM(K5:K10) -> 700860.06 | ... P11: =SUM(P5:P10) -> 25620 | Q11: =SUM(Q5:Q8) -> 25620 | R11: =SUM(R5:R8) -> 25620 | T11: =SUM(C11:S11) -> 1262171.4
T12: =SUM(C12:S12) -> 0
A13: ==== | G13: ='===='!D3 -> 0 | H13: ='===='!E3 -> 0 | I13: ='===='!F3 -> 0 | J13: ='===='!G3 -> 0 | K13: ='===='!H3 -> 0 | L13: ='===='!I3 -> 0 | M13: ='===='!J3 -> 0 | N13: ='===='!K3 -> 0 | ... R13: ='===='!O3 -> 0 | T13: =SUM(C13:S13) -> 0
A14: Salari e Stipendi | C14: ='Salari e Stipendi'!D3 -> 0 | D14: ='Salari e Stipendi'!E3 -> 0 | E14: ='Salari e Stipendi'!F3 -> 0 | F14: ='Salari e Stipendi'!G3 -> 0 | G14: ='Salari e Stipendi'!H3 -> 0 | H14: ='Salari e Stipendi'!I3 -> 0 | I14: ='Salari e Stipendi'!J3 -> 0 | J14: ='Salari e Stipendi'!K3 -> 0 | ... R14: ='Salari e Stipendi'!S3 -> 0 | T14: =SUM(C14:S14) -> 430000
A15: Utenze | C15: =Utenze!D3 -> 0 | D15: =Utenze!E3 -> 0 | E15: =Utenze!F3 -> 0 | F15: =Utenze!G3 -> 0 | G15: =Utenze!H3 -> 0 | H15: =Utenze!I3 -> 0 | I15: =Utenze!J3 -> 0 | J15: =Utenze!K3 -> 0 | ... R15: =Utenze!S3 -> 0 | T15: =SUM(C15:S15) -> 166772.14
A16: Materie Prime/Consumo | C16: ='Materie Prime-Consumo '!D3 -> 0 | D16: ='Materie Prime-Consumo '!E3 -> 0 | E16: ='Materie Prime-Consumo '!F3 -> 0 | F16: ='Materie Prime-Consumo '!G3 -> 0 | G16: ='Materie Prime-Consumo '!H3 -> 0 | H16: ='Materie Prime-Consumo '!I3 -> 0 | I16: ='Materie Prime-Consumo '!J3 -> 0 | J16: ='Materie Prime-Consumo '!K3 -> 0 | ... R16: ='Materie Prime-Consumo '!S3 -> 0 | T16: =SUM(C16:S16) -> 253483.9
A17: Tasse e Imposte | C17: ='Materie Prime-Consumo '!D4 | D17: ='Tasse e Imposte'!E3 -> 0 | E17: ='Tasse e Imposte'!D3 -> 0 | F17: ='Tasse e Imposte'!E3 -> 0 | G17: ='Tasse e Imposte'!F3 -> 0 | H17: ='Tasse e Imposte'!G3 -> 0 | I17: ='Tasse e Imposte'!H3 -> 0 | J17: ='Tasse e Imposte'!I3 -> 0 | K17: ='Tasse e Imposte'!J3 -> 0 | L17: ='Tasse e Imposte'!K3 -> 0 | ... R17: ='Tasse e Imposte'!Q3 -> 10000 | T17: =SUM(C17:S17) -> 130623.85
A18: Commissioni Portali | C18: ='Materie Prime-Consumo '!D8 | D18: ='Commisisoni Portali'!E3 -> 0 | E18: ='Salari e Stipendi'!F7 | F18: ='Commisisoni Portali'!G3 -> 0 | G18: ='Commisisoni Portali'!H3 -> 0 | H18: ='Commisisoni Portali'!I3 -> 0 | I18: ='Commisisoni Portali'!J3 -> 0 | J18: ='Commisisoni Portali'!K3 -> 0 | K18: ='Commisisoni Portali'!L3 -> 49419.62 | L18: ='Commisisoni Portali'!M3 -> 42229.5 | M18: ='Commisisoni Portali'!N3 -> 20573.9 | ... R18: ='Commisisoni Portali'!S3 -> 0 | T18: =SUM(C18:S18) -> 113007.68
A19: Mutui e Finaziamenti | C19: ='Materie Prime-Consumo '!D9 | F19: ='Mutui e Finaziamenti'!G3 -> 0 | G19: ='Mutui e Finaziamenti'!H3 -> 0 | H19: ='Mutui e Finaziamenti'!I3 -> 0 | I19: ='Mutui e Finaziamenti'!J3 -> 0 | J19: ='Mutui e Finaziamenti'!K3 -> 0 | K19: ='Mutui e Finaziamenti'!L3 -> 13621.33 | L19: ='Mutui e Finaziamenti'!M3 -> 13665.58 | M19: ='Mutui e Finaziamenti'!N3 -> 13622.3 | N19: ='Mutui e Finaziamenti'!O3 -> 86464.2 | O19: ='Mutui e Finaziamenti'!L3 -> 13621.33 | P19: ='Mutui e Finaziamenti'!M3 -> 13665.58 | Q19: ='Mutui e Finaziamenti'!N3 -> 13622.3 | R19: ='Mutui e Finaziamenti'!O3 -> 86464.2 | T19: =SUM(C19:S19) -> 254746.82
A20: Consulenze | C20: =Consulenze!D3 -> 0 | D20: =Consulenze!E3 -> 0 | E20: =Consulenze!F3 -> 0 | F20: =Consulenze!G3 -> 0 | G20: =Consulenze!H3 -> 0 | H20: =Consulenze!I3 -> 0 | I20: =Consulenze!J3 -> 0 | J20: =Consulenze!K3 -> 0 | ... R20: =Consulenze!S3 -> 0 | T20: =SUM(C20:S20) -> 23897.43
A21: Godimento Beni di Terzi | C21: ='Godimento Beni di Terzi'!D3 -> 0 | D21: ='Godimento Beni di Terzi'!E3 -> 0 | E21: ='Godimento Beni di Terzi'!F3 -> 0 | F21: ='Godimento Beni di Terzi'!G3 -> 0 | G21: ='Godimento Beni di Terzi'!H3 -> 0 | H21: ='Godimento Beni di Terzi'!I3 -> 0 | I21: ='Godimento Beni di Terzi'!J3 -> 0 | J21: ='Godimento Beni di Terzi'!K3 -> 0 | ... R21: ='Godimento Beni di Terzi'!S3 -> 0 | T21: =SUM(C21:S21) -> 336000
A22: Varie ed Eventuali | C22: 0 | F22: =' Varie ed Eventuali'!G3 -> 0 | G22: =' Varie ed Eventuali'!H3 -> 0 | H22: =' Varie ed Eventuali'!I3 -> 0 | I22: =' Varie ed Eventuali'!J3 -> 0 | J22: =' Varie ed Eventuali'!K3 -> 0 | K22: =' Varie ed Eventuali'!L3 -> 20000 | L22: =' Varie ed Eventuali'!M3 -> 20000 | M22: =' Varie ed Eventuali'!N3 -> 20000 | ... R22: =' Varie ed Eventuali'!S3 -> 20000 | T22: =SUM(C22:S22) -> 160000
A23: Canoni e servizi | D23: ='Canoni e servizi'!E3 -> 0 | E23: ='Canoni e servizi'!F3 -> 0 | F23: ='Canoni e servizi'!G3 -> 0 | G23: ='Canoni e servizi'!H3 -> 0 | H23: ='Canoni e servizi'!I3 -> 0 | I23: ='Canoni e servizi'!J3 -> 0 | J23: ='Canoni e servizi'!K3 -> 0 | K23: ='Canoni e servizi'!L3 -> 30311.72 | ... R23: ='Canoni e servizi'!S3 -> 1551.63 | T23: =SUM(C23:S23) -> 77993.01
A24: Ristr. Apt SDP Jr | C24: ='Ristr. Apt SDP Jr'!E3 -> 0 | D24: ='Ristr. Apt SDP Jr'!F4 | E24: ='Ristr. Apt SDP Jr'!F4 | F24: ='Ristr. Apt SDP Jr'!G4 | G24: ='Ristr. Apt SDP Jr'!H4 | H24: ='Ristr. Apt SDP Jr'!I4 | I24: ='Ristr. Apt SDP Jr'!J4 | J24: ='Ristr. Apt SDP Jr'!K4 | K24: ='Ristr. Apt SDP Jr'!L4 | L24: ='Ristr. Apt SDP Jr'!M4 | ... R24: ='Ristr. Apt SDP Jr'!S4 | T24: =SUM(C24:S24) -> 0
A25: Deposito Fitto | T25: =SUM(C25:S25) -> 0
T26: =SUM(C26:S26) -> 0
T27: =SUM(C27:S27) -> 0
A28: TOTALE USCITE | C28: =SUM(C13:C27) -> 0 | D28: =SUM(D13:D27) -> 0 | E28: =SUM(E13:E27) -> 0 | F28: =SUM(F13:F27) -> 0 | G28: =SUM(G13:G27) -> 0 | H28: =SUM(H13:H27) -> 0 | I28: =SUM(I13:I27) -> 0 | J28: =SUM(J13:J27) -> 0 | ... R28: =SUM(R13:R27) -> 118015.83 | T28: =SUM(C28:S28) -> 1946524.8
T29: =SUM(C29:S29) -> 0
A30: Cash Flow | C30: =C11-C28 -> 0 | D30: =D11-D28 -> 0 | E30: =E11-E28 -> 0 | F30: =F11-F28 -> 0 | G30: =G11-G28 -> 0 | H30: =H11-H28 -> 0 | I30: =I11-I28 -> 0 | J30: =J11-J28 -> 0 | ... R30: =R11-R28 -> -92395.83 | T30: =T11-T28 -> -684353.48
D31: , | T31: =SUM(C31:S31) -> 0
C32: 0 | T32: =SUM(C32:S32) -> 0
A33: Saldo MPS | K33: 1119503.3 | T33: =SUM(C33:S33) -> 1119503.3
A34: Saldo Intesa | K34: 91197.46 | T34: =SUM(C34:S34) -> 91197.46
T35: =SUM(C35:S35) -> 0
A36: TOTALE BANCHE | C36: =SUM(C31:C35) -> 0 | D36: =C40 -> 0 | E36: =D40 -> 0 | F36: =E40 -> 0 | G36: =F40 -> 0 | K36: =K33+K34 -> 1210700.7 | L36: =M33+M34+L35 -> 0 | M36: =N33+N34+M35 -> 0 | N36: =O33+O34+N35 -> 0 | O36: =P33+P34+O35 -> 0 | P36: =Q33+Q34+P35 -> 0 | Q36: =R33+R34+Q35 -> 0 | R36: =S33+S34+R35 -> 0 | T36: =T30+T33+T34 -> 526347.24
T37: =SUM(C37:S37) -> 0
A38: CASSA CONTANTI | E38: 0 | F38: 0 | G38: 0 | H38: 0 | I38: 0 | J38: 0 | K38: 0 | L38: 0 | M38: 0 | N38: 0 | O38: 0 | P38: 0 | Q38: 0 | R38: 0 | T38: =SUM(C38:S38) -> 0
T39: =SUM(C39:S39) -> 0
A40: Saldo di Periodo/Proiettato | C40: =C36+C30 -> 0 | D40: =D30+D36 -> 0 | E40: =E30+E36 -> 0 | F40: =F30+F36 -> 0 | G40: =G30+G36 -> 0 | H40: =H30+H36 -> 0 | I40: =I3+I30 -> 0 | J40: =J3+J30 -> 0 | K40: =K3+K30 -> 1405286.3 | L40: =L3+L30 -> 1330621.4 | M40: =M3+M30 -> 1008715.6 | N40: =N3+N30 -> 786654.08 | O40: =O3+O30 -> 653447.21 | P40: =P3+P30 -> 631943 | ... R40: =R3+R30 -> 526347.24 | T40: =R40-T36 -> -1.1641532e-10
...

Sheet ====
D1: 2025 | P1: 2026
D2: GENNAIO | E2: FEBBRAIO | F2: MARZO | G2: APRILE | H2: MAGGIO | I2: GIUGNO | J2: LUGLIO | K2: AGOSTO | L2: SETTEMBRE | M2: OTTOBRE | N2: NOVEMBRE | O2: DICEMBRE | P2: GENNAIO | Q2: FEBBRAIO | R2: MARZO | S2: APRILE
B3: Totale Lavori 2024 | C3: =SUM(D3:S3) -> 0 | D3: =SUM(D4:D134) -> 0 | E3: =SUM(E4:E134) -> 0 | F3: =SUM(F4:F134) -> 0 | G3: =SUM(G4:G134) -> 0 | H3: =SUM(H4:H134) -> 0 | I3: =SUM(I4:I134) -> 0 | J3: =SUM(J4:J134) -> 0 | K3: =SUM(K4:K134) -> 0 | ... O3: =SUM(O4:O134) -> 0
C4: =SUM(D4:S4) -> 0
C5: =SUM(D5:S5) -> 0
C6: =SUM(D6:S6) -> 0
C7: =SUM(D7:S7) -> 0
C8: =SUM(D8:S8) -> 0
C9: =SUM(D9:S9) -> 0
C10: =SUM(D10:S10) -> 0
C11: =SUM(D11:S11) -> 0
C12: =SUM(D12:S12) -> 0
C13: =SUM(D13:S13) -> 0
C14: =SUM(D14:S14) -> 0
C15: =SUM(D15:S15) -> 0
... C68: =SUM(D68:S68) -> 0

Sheet Salari e Stipendi
D1: 2025 | P1: 2026
D2: GENNAIO | E2: FEBBRAIO | F2: MARZO | G2: APRILE | H2: MAGGIO | I2: GIUGNO | J2: LUGLIO | K2: AGOSTO | L2: SETTEMBRE | M2: OTTOBRE | N2: NOVEMBRE | O2: DICEMBRE | P2: GENNAIO | Q2: FEBBRAIO | R2: MARZO | S2: APRILE
B3: Salari e Stipendi | C3: =SUM(D3:S3) -> 430000 | D3: =SUM(D4:D134) -> 0 | E3: =SUM(E4:E134) -> 0 | F3: =SUM(F4:F134) -> 0 | G3: =SUM(G4:G134) -> 0 | H3: =SUM(H4:H134) -> 0 | I3: =SUM(I4:I134) -> 0 | J3: =SUM(J4:J134) -> 0 | K3: =SUM(K4:K134) -> 0 | ... S3: =SUM(S4:S134) -> 0
B4: SALARI | C4: =SUM(D4:S4) -> 234000 | D4: 0 | E4: 0 | F4: 0 | M4: 80000 | N4: 90000 | O4: 42000 | P4: 22000
B5: F24 | C5: =SUM(D5:S5) -> 196000 | D5: 0 | E5: 0 | F5: 0 | L5: 50000 | M5: 55000 | N5: 55000 | O5: 18000 | P5: 18000
C6: =SUM(D6:S6) -> 0
C7: =SUM(D7:S7) -> 0
C8: =SUM(D8:S8) -> 0
C9: =SUM(D9:S9) -> 0
C10: =SUM(D10:S10) -> 0
C11: =SUM(D11:S11) -> 0
C12: =SUM(D12:S12) -> 0
C13: =SUM(D13:S13) -> 0
C14: =SUM(D14:S14) -> 0
C15: =SUM(D15:S15) -> 0
C16: =SUM(D16:S16) -> 0
C17: =SUM(D17:S17) -> 0
... C68: =SUM(D68:S68) -> 0

Sheet Materie Prime-Consumo 
D1: 2025 | P1: 2026
D2: GENNAIO | E2: FEBBRAIO | F2: MARZO | G2: APRILE | H2: MAGGIO | I2: GIUGNO | J2: LUGLIO | K2: AGOSTO | L2: SETTEMBRE | M2: OTTOBRE | N2: NOVEMBRE | O2: DICEMBRE | P2: GENNAIO | Q2: FEBBRAIO | R2: MARZO | S2: APRILE
B3: Materie Prime e Consumo | C3: =SUM(D3:S3) -> 253483.9 | D3: =SUM(D4:D169) -> 0 | E3: =SUM(E4:E169) -> 0 | F3: =SUM(F4:F169) -> 0 | G3: =SUM(G4:G169) -> 0 | H3: =SUM(H4:H169) -> 0 | I3: =SUM(I4:I169) -> 0 | J3: =SUM(J4:J169) -> 0 | K3: =SUM(K4:K169) -> 0 | ... S3: =SUM(S4:S169) -> 0
B4: A. Migliore srl | C4: =SUM(D4:S4) -> 3923.96 | L4: 1028.55 | M4: =3923.96-L4 -> 2895.41
B5: Abiti da lavoro Cavaliere srls | C5: =SUM(D5:S5) -> 379.42 | L5: 379.42
B6: Adra srl | C6: =SUM(D6:S6) -> 2165.67 | L6: 664.75 | M6: =1513.36-L6 -> 848.61 | N6: =2165.67-M6-L6 -> 652.31
B7: Affinito srl | C7: =SUM(D7:S7) -> 389.5 | L7: 389.5
B8: Alberto D'Urso | C8: =SUM(D8:S8) -> 137.82 | L8: 137.82
B9: Amalfi sei esse | C9: =SUM(D9:S9) -> 29464.46 | L9: 5668.45 | M9: =13962.84-L9 -> 8294.39 | N9: =21205.36-M9-L9 -> 7242.52 | O9: =29464.46-N9-M9-L9 -> 8259.1
B10: Amato Filippo | C10: =SUM(D10:S10) -> 220 | L10: 220
B11: Alfera srl | C11: =SUM(D11:S11) -> 4516 | L11: 2679 | M11: 1837
B12: Allestimenti Di Palo | C12: =SUM(D12:S12) -> 567.3 | L12: 567.3
B13: Amato Prisco pane | C13: =SUM(D13:S13) -> 1135.68 | L13: 1135.68
B14: Aniello Bisogno & Figli | C14: =SUM(D14:S14) -> 1610.4 | L14: 1610.4
B15: Attianese Frutta e Verdura | C15: =SUM(D15:S15) -> 7394.8 | L15: 3343.14 | M15: =7394.8-L15 -> 4051.66
B16: Apicella Lorenzo | C16: =SUM(D16:S16) -> 400 | L16: 400
B17: B&G Di Palo Commercio | C17: =SUM(D17:S17) -> 1253.81 | L17: 176.46 | M17: 1077.35
B18: Bellagaia | C18: =SUM(D18:S18) -> 10078.37 | L18: 4888.6 | M18: =10047.44-L18 -> 5158.84 | N18: 30.93
B19: Campitiello Fabio | C19: =SUM(D19:S19) -> 70 | L19: 70
B20: Casa Vinicola Sammarco | C20: =SUM(D20:S20) -> 2725.97 | M20: 863.76 | N20: 1862.21
B21: Caseificio Green Valley | C21: =SUM(D21:S21) -> 2543.84 | L21: 2543.84
B22: Centro Distribuzione Maglio | C22: =SUM(D22:S22) -> 2382.6 | L22: 1128.6 | M22: 1254
B23: Centro service Snc | C23: =SUM(D23:S23) -> 1876.16 | L23: =1876.16-K23 -> 1876.16
B24: Cica | C24: =SUM(D24:S24) -> 5868.89 | L24: 3126.38 | M24: =5440.35-L24 -> 2313.97 | N24: 428.54
B25: Cimmini Filomena | C25: =SUM(D25:S25) -> 51.48 | L25: 51.48
B26: Creative Idea | C26: =SUM(D26:S26) -> 4026 | L26: 4026
B27: Cuzziol grandi Vini | C27: =SUM(D27:S27) -> 1908.08 | L27: 954.04 | M27: 954.04
B28: DG Network | C28: =SUM(D28:S28) -> 684.42 | L28: 684.42
B29: Di Sarno Coffee | C29: =SUM(D29:S29) -> 12871.46 | L29: 11695.82 | M29: 1175.64
B30: Ditta Apicella | C30: =SUM(D30:S30) -> 79.3 | L30: 79.3
B31: Fabbrocino Michele | C31: =SUM(D31:S31) -> 17432.97 | L31: 2102.74 | M31: 4183.28 | N31: 5566.85 | O31: 5580.1
B32: Barela Farmacia | C32: =SUM(D32:S32) -> 33.8 | L32: 33.8
B33: Feio Srl | C33: =SUM(D33:S33) -> 1262.7 | L33: 1218.78 | M33: 43.92
B34: Ferrigno Maria | C34: =SUM(D34:S34) -> 33 | L34: 33
B35: General Beverage | C35: =SUM(D35:S35) -> 934.89 | L35: 934.89
B36: Giacinto Di Palma | C36: =SUM(D36:S36) -> 365.17 | L36: 217.23 | M36: 147.94
B37: Granato Vincenzo | C37: =SUM(D37:S37) -> 4374.94 | L37: 4374.94
B38: Granato Nino | C38: =SUM(D38:S38) -> 976 | L38: 976
B39: Hotel Service | C39: =SUM(D39:S39) -> 32112.04 | L39: 13974.44 | M39: =32112.04-L39 -> 18137.6
B40: I.C.P srl | C40: =SUM(D40:S40) -> 7671.05 | L40: =4741.02-J40 -> 4741.02 | M40: =6513.38-L40 -> 1772.36 | N40: =7671.05-L40-M40 -> 1157.67
...

Sheet Utenze
D1: 2025 | P1: 2026
D2: GENNAIO | E2: FEBBRAIO | F2: MARZO | G2: APRILE | H2: MAGGIO | I2: GIUGNO | J2: LUGLIO | K2: AGOSTO | L2: SETTEMBRE | M2: OTTOBRE | N2: NOVEMBRE | O2: DICEMBRE | P2: GENNAIO | Q2: FEBBRAIO | R2: MARZO | S2: APRILE
B3: Utenze | C3: =SUM(D3:S3) -> 166772.14 | D3: =SUM(D4:D134) -> 0 | E3: =SUM(E4:E134) -> 0 | F3: =SUM(F4:F134) -> 0 | G3: =SUM(G4:G134) -> 0 | H3: =SUM(H4:H134) -> 0 | I3: =SUM(I4:I134) -> 0 | J3: =SUM(J4:J134) -> 0 | K3: =SUM(K4:K134) -> 0 | ... S3: =SUM(S4:S134) -> 0
A4: RID | B4: Energia elettrica | C4: =SUM(D4:S4) -> 95180 | D4: 0 | E4: 0 | F4: 0 | J4: 0 | K4: 0 | L4: 26050 | M4: 28200 | N4: 19800 | O4: 13600 | P4: 4520 | Q4: 3010
A5: RID | B5: Gas | C5: =SUM(D5:S5) -> 29750 | D5: 0 | E5: 0 | F5: 0 | J5: 0 | L5: 6000 | M5: 5700 | N5: 6050 | O5: 5800 | P5: 3200 | Q5: 3000
B6: Ausino | C6: =SUM(D6:S6) -> 24000 | D6: 0 | E6: 0 | L6: 9000 | N6: 8000 | P6: 3500 | R6: 3500
A7: RID | B7: Vodafone | C7: =SUM(D7:S7) -> 6000 | E7: 0 | M7: 3000 | O7: 3000
B8: Connectivia | C8: =SUM(D8:S8) -> 11842.14 | E8: 0 | L8: 3442.14 | M8: 5000 | O8: 3400
C9: =SUM(D9:S9) -> 0
C10: =SUM(D10:S10) -> 0
C11: =SUM(D11:S11) -> 0
C12: =SUM(D12:S12) -> 0
C13: =SUM(D13:S13) -> 0
C14: =SUM(D14:S14) -> 0
C15: =SUM(D15:S15) -> 0
C16: =SUM(D16:S16) -> 0
C17: =SUM(D17:S17) -> 0
C18: =SUM(D18:S18) -> 0
C19: =SUM(D19:S19) -> 0
C20: =SUM(D20:S20) -> 0
... C68: =SUM(D68:S68) -> 0

Sheet Commisisoni Portali
D1: 2025 | P1: 2026
D2: GENNAIO | E2: FEBBRAIO | F2: MARZO | G2: APRILE | H2: MAGGIO | I2: GIUGNO | J2: LUGLIO | K2: AGOSTO | L2: SETTEMBRE | M2: OTTOBRE | N2: NOVEMBRE | O2: DICEMBRE | P2: GENNAIO | Q2: FEBBRAIO | R2: MARZO | S2: APRILE
B3: Commisisoni Portali | C3: =SUM(D3:S3) -> 113007.68 | D3: =SUM(D4:D130) -> 0 | E3: =SUM(E4:E130) -> 0 | F3: =SUM(F4:F130) -> 0 | G3: =SUM(G4:G130) -> 0 | H3: =SUM(H4:H130) -> 0 | I3: =SUM(I4:I130) -> 0 | J3: =SUM(J4:J130) -> 0 | K3: =SUM(K4:K130) -> 0 | ... S3: =SUM(S4:S130) -> 0
B4: Commissioni Booking | C4: =SUM(D4:S4) -> 92438.79 | L4: 43419.62 | M4: 34291.5 | N4: 14048.63 | O4: 679.04
B5: Commissioni Expedia | C5: =SUM(D5:S5) -> 20568.89 | L5: 6000 | M5: 7938 | N5: 6525.27 | O5: 105.62
C6: =SUM(D6:S6) -> 0
C7: =SUM(D7:S7) -> 0
C8: =SUM(D8:S8) -> 0
C9: =SUM(D9:S9) -> 0
C10: =SUM(D10:S10) -> 0
C11: =SUM(D11:S11) -> 0
C12: =SUM(D12:S12) -> 0
C13: =SUM(D13:S13) -> 0
C14: =SUM(D14:S14) -> 0
C15: =SUM(D15:S15) -> 0
C16: =SUM(D16:S16) -> 0
C17: =SUM(D17:S17) -> 0
... C64: =SUM(D64:S64) -> 0

Sheet Tasse e Imposte
D1: 2025 | P1: 2026
D2: GENNAIO | E2: FEBBRAIO | F2: MARZO | G2: APRILE | H2: MAGGIO | I2: GIUGNO | J2: LUGLIO | K2: AGOSTO | L2: SETTEMBRE | M2: OTTOBRE | N2: NOVEMBRE | O2: DICEMBRE | P2: GENNAIO | Q2: FEBBRAIO | R2: MARZO | S2: APRILE
B3: Tasse e Imposte | C3: =SUM(D3:S3) -> 130623.85 | D3: =SUM(D4:D135) -> 0 | E3: =SUM(E4:E135) -> 0 | F3: =SUM(F4:F135) -> 0 | G3: =SUM(G4:G135) -> 0 | H3: =SUM(H4:H135) -> 0 | I3: =SUM(I4:I135) -> 0 | J3: =SUM(J4:J135) -> 0 | K3: =SUM(K4:K135) -> 0 | ... S3: =SUM(S4:S135) -> 0
B4: IMU | C4: =SUM(D4:S4) -> 5109 | O4: 5109
B5: IMPOSTE | C5: =SUM(D5:S5) -> 7500 | N5: 7500
B6: TARI HOTEL | C6: =SUM(D6:S6) -> 0 | N6: 0
B7: IVA | C7: =SUM(D7:S7) -> 60000 | N7: 50000 | Q7: 10000
B8: RITENUTE PROFESSIONISTI (1040) | L8: 1000
B9: IMPOSTA DI SOGGIORNO HP | C9: =SUM(D9:S9) -> 48692 | L9: 17272 | M9: 18020 | N9: 12828 | O9: 572
B10: IMPOSTA DI SOGGIORNO AR | C10: =SUM(D10:S10) -> 4862.847 | L10: =7474*0.3333 -> 2491.0842 | M10: =4344*0.3333 -> 1447.8552 | N10: =2574*0.3333 -> 857.9142 | O10: =198*0.3333 -> 65.9934
B11: IMPOSTA DI SOGGIORNO CVM | C11: =SUM(D11:S11) -> 3460 | L11: 1604 | M11: 812 | N11: 748 | O11: 150 | P11: 146
B12: TARI RESIDENCE | C12: =SUM(D12:S12) -> 0
B13: TARI CVM | C13: =SUM(D13:S13) -> 0
C14: =SUM(D14:S14) -> 0
C15: =SUM(D15:S15) -> 0
C16: =SUM(D16:S16) -> 0
C17: =SUM(D17:S17) -> 0
C18: =SUM(D18:S18) -> 0
C19: =SUM(D19:S19) -> 0
C20: =SUM(D20:S20) -> 0
C21: =SUM(D21:S21) -> 0
C22: =SUM(D22:S22) -> 0
C23: =SUM(D23:S23) -> 0
C24: =SUM(D24:S24) -> 0
C25: =SUM(D25:S25) -> 0
... C69: =SUM(D69:S69) -> 0

Sheet Mutui e Finaziamenti
D1: 2025 | P1: 2026
D2: GENNAIO | E2: FEBBRAIO | F2: MARZO | G2: APRILE | H2: MAGGIO | I2: GIUGNO | J2: LUGLIO | K2: AGOSTO | L2: SETTEMBRE | M2: OTTOBRE | N2: NOVEMBRE | O2: DICEMBRE | P2: GENNAIO | Q2: FEBBRAIO | R2: MARZO | S2: APRILE
B3: Mutui e Finanaziamenti | C3: =SUM(D3:S3) -> 181869.57 | D3: =SUM(D4:D134) -> 0 | E3: =SUM(E4:E134) -> 0 | F3: =SUM(F4:F134) -> 0 | G3: =SUM(G4:G134) -> 0 | H3: =SUM(H4:H134) -> 0 | I3: =SUM(I4:I134) -> 0 | J3: =SUM(J4:J134) -> 0 | K3: =SUM(K4:K134) -> 0 | ... S3: =SUM(S4:S134) -> 13624.79
B4: Mutuo MPS | C4: =SUM(D4:S4) -> 72800 | O4: 72800
B5: Muto Intesa | C5: =SUM(D5:S5) -> 97918.21 | L5: 12227.41 | M5: 12271.66 | N5: 12228.38 | O5: 12270.28 | P5: 12269.58 | Q5: 12151.84 | R5: 12268.19 | S5: 12230.87
B6: Finanziamento MPS 75k | C6: =SUM(D6:S6) -> 11151.36 | L6: 1393.92 | M6: 1393.92 | N6: 1393.92 | O6: 1393.92 | P6: 1393.92 | Q6: 1393.92 | R6: 1393.92 | S6: 1393.92
C7: =SUM(D7:S7) -> 0
C8: =SUM(D8:S8) -> 0
C9: =SUM(D9:S9) -> 0
C10: =SUM(D10:S10) -> 0
C11: =SUM(D11:S11) -> 0
C12: =SUM(D12:S12) -> 0
C13: =SUM(D13:S13) -> 0
C14: =SUM(D14:S14) -> 0
C15: =SUM(D15:S15) -> 0
C16: =SUM(D16:S16) -> 0
C17: =SUM(D17:S17) -> 0
C18: =SUM(D18:S18) -> 0
... C68: =SUM(D68:S68) -> 0

Sheet Canoni e servizi
D1: 2025 | P1: 2026
D2: GENNAIO | E2: FEBBRAIO | F2: MARZO | G2: APRILE | H2: MAGGIO | I2: GIUGNO | J2: LUGLIO | K2: AGOSTO | L2: SETTEMBRE | M2: OTTOBRE | N2: NOVEMBRE | O2: DICEMBRE | P2: GENNAIO | Q2: FEBBRAIO | R2: MARZO | S2: APRILE
B3: Canoni e servizi | C3: =SUM(D3:S3) -> 77993.01 | D3: =SUM(D4:D131) -> 0 | E3: =SUM(E4:E131) -> 0 | F3: =SUM(F4:F131) -> 0 | G3: =SUM(G4:G131) -> 0 | H3: =SUM(H4:H131) -> 0 | I3: =SUM(I4:I131) -> 0 | J3: =SUM(J4:J131) -> 0 | K3: =SUM(K4:K131) -> 0 | ... S3: =SUM(S4:S131) -> 1551.63
B4: Proxima Service | C4: =SUM(D4:S4) -> 7502.64 | O4: =6602.64+900 -> 7502.64
B5: Hoxell | C5: =SUM(D5:S5) -> 2200 | L5: 2200
B6: Sistemi (E_solver) | C6: =SUM(D6:S6) -> 3615 | L6: 1205 | M6: 1205 | O6: 1205
B7: Zucchetti | C7: =SUM(D7:S7) -> 0
B8: Pin App | C8: =SUM(D8:S8) -> 0
B9: Spiagge | C9: =SUM(D9:S9) -> 0
B10: Altamira | C10: =SUM(D10:S10) -> 780.8 | L10: 97.6 | M10: 97.6 | N10: 97.6 | O10: 97.6 | P10: 97.6 | Q10: 97.6 | R10: 97.6 | S10: 97.6
B11: Amalfi Web | C11: =SUM(D11:S11) -> 5321.64 | L11: 5321.64
B12: Commissioni Transato Pos | C12: =SUM(D12:S12) -> 41940.69 | L12: 18033.45 | M12: 15731.32 | N12: 7362.04 | O12: 813.88
B13: Software tecnology | C13: =SUM(D13:S13) -> 1000 | M13: 500 | P13: 500
B14: Commissioni e spese Bancarie Varie(Imposta di bollo/tenuta conto/bonifici/etc ) | C14: =SUM(D14:S14) -> 4000 | L14: 2000 | O14: 2000
B15: Noleggio Tesla | C15: =SUM(D15:S15) -> 8245.12 | L15: 1030.64 | M15: 1030.64 | N15: 1030.64 | O15: 1030.64 | P15: 1030.64 | Q15: 1030.64 | R15: 1030.64 | S15: 1030.64
B16: Alba Leasing S.P.A. | C16: =SUM(D16:S16) -> 3387.12 | L16: 423.39 | M16: 423.39 | N16: 423.39 | O16: 423.39 | P16: 423.39 | Q16: 423.39 | R16: 423.39 | S16: 423.39
C17: =SUM(D17:S17) -> 0
C18: =SUM(D18:S18) -> 0
C19: =SUM(D19:S19) -> 0
C20: =SUM(D20:S20) -> 0
C21: =SUM(D21:S21) -> 0
C22: =SUM(D22:S22) -> 0
C23: =SUM(D23:S23) -> 0
C24: =SUM(D24:S24) -> 0
C25: =SUM(D25:S25) -> 0
C26: =SUM(D26:S26) -> 0
C27: =SUM(D27:S27) -> 0
C28: =SUM(D28:S28) -> 0
... C66: =SUM(D66:S66) -> 0

Sheet Godimento Beni di Terzi
D1: 2025 | P1: 2026
D2: GENNAIO | E2: FEBBRAIO | F2: MARZO | G2: APRILE | H2: MAGGIO | I2: GIUGNO | J2: LUGLIO | K2: AGOSTO | L2: SETTEMBRE | M2: OTTOBRE | N2: NOVEMBRE | O2: DICEMBRE | P2: GENNAIO | Q2: FEBBRAIO | R2: MARZO | S2: APRILE
B3: Gofimento Beni di Terzi | C3: =SUM(D3:S3) -> 336000 | D3: =SUM(D4:D134) -> 0 | E3: =SUM(E4:E134) -> 0 | F3: =SUM(F4:F134) -> 0 | G3: =SUM(G4:G134) -> 0 | H3: =SUM(H4:H134) -> 0 | I3: =SUM(I4:I134) -> 0 | J3: =SUM(J4:J134) -> 0 | K3: =SUM(K4:K134) -> 0 | ... S3: =SUM(S4:S134) -> 0
B4: Fitto Ramo d' Azienda | C4: =SUM(D4:S4) -> 116000 | L4: 116000
B5: Fitto AR | C5: =SUM(D5:S5) -> 120000 | M5: 120000
B6: Fitto CVM | C6: =SUM(D6:S6) -> 100000 | L6: 50000 | M6: 0 | N6: 50000
C7: =SUM(D7:S7) -> 0
C8: =SUM(D8:S8) -> 0
C9: =SUM(D9:S9) -> 0
C10: =SUM(D10:S10) -> 0
C11: =SUM(D11:S11) -> 0
C12: =SUM(D12:S12) -> 0
C13: =SUM(D13:S13) -> 0
C14: =SUM(D14:S14) -> 0
C15: =SUM(D15:S15) -> 0
C16: =SUM(D16:S16) -> 0
C17: =SUM(D17:S17) -> 0
C18: =SUM(D18:S18) -> 0
... C68: =SUM(D68:S68) -> 0

Sheet Consulenze
D1: 2025 | P1: 2026
D2: GENNAIO | E2: FEBBRAIO | F2: MARZO | G2: APRILE | H2: MAGGIO | I2: GIUGNO | J2: LUGLIO | K2: AGOSTO | L2: SETTEMBRE | M2: OTTOBRE | N2: NOVEMBRE | O2: DICEMBRE | P2: GENNAIO | Q2: FEBBRAIO | R2: MARZO | S2: APRILE
B3: Consulenze | C3: =SUM(D3:S3) -> 23897.43 | D3: =SUM(D4:D136) -> 0 | E3: =SUM(E4:E136) -> 0 | F3: =SUM(F4:F136) -> 0 | G3: =SUM(G4:G136) -> 0 | H3: =SUM(H4:H136) -> 0 | I3: =SUM(I4:I136) -> 0 | J3: =SUM(J4:J136) -> 0 | K3: =SUM(K4:K136) -> 0 | ... S3: =SUM(S4:S136) -> 0
B4: Consulenza del lavoro | C4: =SUM(D4:S4) -> 7528.47 | M4: 2528.47 | N4: 5000
B5: Consulenza fiscale | C5: =SUM(D5:S5) -> 10000 | M5: 5000 | O5: 5000
B6: Consulenza legale | C6: =SUM(D6:S6) -> 0
B7: Autiero Architetto | C7: =SUM(D7:S7) -> 1268.8 | L7: 1268.8
B8: Fiorini architetto | C8: =SUM(D8:S8) -> 1040 | L8: 1040
B9: Marigliano Salvatore Architetto | C9: =SUM(D9:S9) -> 1268.8 | L9: 1268.8
B10: Mint studio di architettura | C10: =SUM(D10:S10) -> 1268.8 | L10: 1268.8
B11: Nese ing. | C11: =SUM(D11:S11) -> 1522.56 | L11: 1522.56
C12: =SUM(D12:S12) -> 0
C13: =SUM(D13:S13) -> 0
C14: =SUM(D14:S14) -> 0
C15: =SUM(D15:S15) -> 0
C16: =SUM(D16:S16) -> 0
C17: =SUM(D17:S17) -> 0
C18: =SUM(D18:S18) -> 0
C19: =SUM(D19:S19) -> 0
C20: =SUM(D20:S20) -> 0
C21: =SUM(D21:S21) -> 0
C22: =SUM(D22:S22) -> 0
C23: =SUM(D23:S23) -> 0
... C70: =SUM(D70:S70) -> 0

Sheet  Varie ed Eventuali
D1: 2025 | P1: 2026
D2: GENNAIO | E2: FEBBRAIO | F2: MARZO | G2: APRILE | H2: MAGGIO | I2: GIUGNO | J2: LUGLIO | K2: AGOSTO | L2: SETTEMBRE | M2: OTTOBRE | N2: NOVEMBRE | O2: DICEMBRE | P2: GENNAIO | Q2: FEBBRAIO | R2: MARZO | S2: APRILE
B3: Variee ed Eventuali | C3: =D3+E3+F3+G3+H3+I3+J3+K3+L3+M3+N3+O3+P3+Q3+R3+R4 -> 160000 | D3: =SUM(D4:D134) -> 0 | E3: =SUM(E4:E134) -> 0 | F3: =SUM(F4:F134) -> 0 | G3: =SUM(G4:G134) -> 0 | H3: =SUM(H4:H134) -> 0 | I3: =SUM(I4:I134) -> 0 | J3: =SUM(J4:J134) -> 0 | K3: =SUM(K4:K134) -> 0 | ... S3: =SUM(S4:S134) -> 20000
C4: =SUM(D4:S4) -> 160000 | E4: 0 | F4: 0 | L4: 20000 | M4: 20000 | N4: 20000 | O4: 20000 | P4: 20000 | Q4: 20000 | R4: 20000 | S4: 20000
B5: Cantiere Carotenuto? | C5: =H5+I5+J5+K5+L5+M5+N5+O5 -> 0
C6: =+H6+I6+J6+K6+L6+M6+N6+O6+G6+F6+E6 -> 0
C7: =H7+I7+J7+K7+L7+M7+N7+O7 -> 0
C8: =H8+I8+J8+K8+L8+M8+N8+O8 -> 0
C9: =H9+I9+J9+K9+L9+M9+N9+O9 -> 0
C10: =H10+I10+J10+K10+L10+M10+N10+O10 -> 0
C11: =F11+G11+H11+I11+J11+K11+L11+M11+N11+O11 -> 0
C12: =+H12+I12+J12+K12+L12+M12+N12+O12+F12+G12 -> 0
C13: =H13+I13+J13+K13+L13+M13+N13+O13 -> 0
C14: =H14+I14+J14+K14+L14+M14+N14+O14 -> 0
C15: =H15+I15+J15+K15+L15+M15+N15+O15 -> 0
C16: =H16+I16+J16+K16+L16+M16+N16+O16 -> 0
C17: =D17+E17+F17+G17+H17+I17+J17+K17+L17+M17+N17+O17+P17+Q17+R17+S17+N17 -> 0
C18: =D18+E18+F18+G18+H18+I18+J18+K18+L18+M18+N18+O18+P18+Q18+R18+S18+N18 -> 0
C19: =D19+E19+F19+G19+H19+I19+J19+K19+L19+M19+N19+O19+P19+Q19+R19+S19+N19 -> 0
C20: =D20+E20+F20+G20+H20+I20+J20+K20+L20+M20+N20+O20+P20+Q20+R20+S20+N20 -> 0
C21: =D21+E21+F21+G21+H21+I21+J21+K21+L21+M21+N21+O21+P21+Q21+R21+S21+N21 -> 0
C22: =D22+E22+F22+G22+H22+I22+J22+K22+L22+M22+N22+O22+P22+Q22+R22+S22+N22 -> 0
C23: =D23+E23+F23+G23+H23+I23+J23+K23+L23+M23+N23+O23+P23+Q23+R23+S23+N23 -> 0
C24: =D24+E24+F24+G24+H24+I24+J24+K24+L24+M24+N24+O24+P24+Q24+R24+S24+N24 -> 0
C25: =D25+E25+F25+G25+H25+I25+J25+K25+L25+M25+N25+O25+P25+Q25+R25+S25+N25 -> 0
C26: =D26+E26+F26+G26+H26+I26+J26+K26+L26+M26+N26+O26+P26+Q26+R26+S26+N26 -> 0
C27: =D27+E27+F27+G27+H27+I27+J27+K27+L27+M27+N27+O27+P27+Q27+R27+S27+N27 -> 0
C28: =D28+E28+F28+G28+H28+I28+J28+K28+L28+M28+N28+O28+P28+Q28+R28+S28+N28 -> 0
... C68: =D68+E68+F68+G68+H68+I68+J68+K68+L68+M68+N68+O68+P68+Q68+R68+S68+N68 -> 0

Sheet Ristr. Apt SDP Jr
E1: 2025 | Q1: 2026
E2: GENNAIO | F2: FEBBRAIO | G2: MARZO | H2: APRILE | I2: MAGGIO | J2: GIUGNO | K2: LUGLIO | L2: AGOSTO | M2: SETTEMBRE | N2: OTTOBRE | O2: NOVEMBRE | P2: DICEMBRE | Q2: GENNAIO | R2: FEBBRAIO | S2: MARZO | T2: APRILE
C3: Stima lavori | D3: =E3+F3+G3+H3+I3+J3+K3+L3+M3+N3+O3+P3+Q3+R3+S3+T3 -> 47000 | E3: =SUM(E4:E134) -> 0 | F3: =SUM(F4:F133) -> 0 | G3: =SUM(G4:G133) -> 0 | H3: =SUM(H4:H133) -> 0 | I3: =SUM(I4:I133) -> 0 | J3: =SUM(J4:J133) -> 0 | K3: =SUM(K4:K133) -> 0 | L3: =SUM(L4:L133) -> 0 | M3: =SUM(M4:M133) -> 47000 | ... S3: =SUM(S4:S133) -> 0
B4: MIELE RI.BA DAL 31/05/2025 | D4: =E5+F5+G5+H5+I4+J4+K4+L4+M5+N5+O5+P5+Q5+R5+S5+T5 -> 47000
B5: ALESSIO | D5: =E6+F6+G6+H6+I6+J6+K6+L6+M6+N6+O6+P6+Q6+R6+S6+T6 -> 0 | G5: 0 | M5: 47000
B6: S.T.E. | C6: 16500 | D6: =E7+F7+G7+H7+I7+J7+K7+L7+M7+N7+O7+P7+Q7+R7+S7+T7 -> 0
B7: PITTORE | C7: 8800 | D7: =E8+F8+G8+H8+I8+J8+K8+L8+M8+N8+O8+P8+Q8+R8+S8+T8 -> 0
B8: INFISSI ROMANO | C8: 4400 | D8: =E9+F9+G9+H9+I9+J9+K9+L9+M9+N9+O9+P9+Q9+R9+S9+T9 -> 0
B9: SANTELIA IMPIANTI | C9: 21466.5 | D9: =E10+F10+G10+H10+I10+J10+K10+L10+M10+N10+O10+P10+Q10+R10+S10+T10 -> 0
B10: NUSCO | C10: 5086.4 | D10: =E11+F11+G11+H11+I11+J11+K11+L11+M11+N11+O11+P11+Q11+R11+S11+T11 -> 0
B11: ARCHITETTO | C11: 12000 | D11: =E12+F12+G12+H12+I12+J12+K12+L12+M12+N12+O12+P12+Q12+R12+S12+T12 -> 0
D12: =E13+F13+G13+H13+I13+J13+K13+L13+M13+N13+O13+P13+Q13+R13+S13+T13 -> 0
D13: =E14+F14+G14+H14+I14+J14+K14+L14+M14+N14+O14+P14+Q14+R14+S14+T14 -> 0
D14: =E15+F15+G15+H15+I15+J15+K15+L15+M15+N15+O15+P15+Q15+R15+S15+T15 -> 0
D15: =E16+F16+G16+H16+I16+J16+K16+L16+M16+N16+O16+P16+Q16+R16+S16+T16 -> 0
D16: =E17+F17+G17+H17+I17+J17+K17+L17+M17+N17+O17+P17+Q17+R17+S17+T17 -> 0
D17: =E18+F18+G18+H18+I18+J18+K18+L18+M18+N18+O18+P18+Q18+R18+S18+T18 -> 0
D18: =E19+F19+G19+H19+I19+J19+K19+L19+M19+N19+O19+P19+Q19+R19+S19+T19 -> 0
D19: =E20+F20+G20+H20+I20+J20+K20+L20+M20+N20+O20+P20+Q20+R20+S20+T20 -> 0
D20: =E21+F21+G21+H21+I21+J21+K21+L21+M21+N21+O21+P21+Q21+R21+S21+T21 -> 0
D21: =E22+F22+G22+H22+I22+J22+K22+L22+M22+N22+O22+P22+Q22+R22+S22+T22 -> 0
D22: =E23+F23+G23+H23+I23+J23+K23+L23+M23+N23+O23+P23+Q23+R23+S23+T23 -> 0
D23: =E24+F24+G24+H24+I24+J24+K24+L24+M24+N24+O24+P24+Q24+R24+S24+T24 -> 0
... D67: =E68+F68+G68+H68+I68+J68+K68+L68+M68+N68+O68+P68+Q68+R68+S68+T68 -> 0
